INFO  | 04/14/2020 05:28:06 PM | File run_exp.py           | Line 26    | Writing log file to exp/GRAN\GRANMixtureBernoulli_transport_2020-Apr-14-17-28-06_7740\log_exp_7740.txt
INFO  | 04/14/2020 05:28:06 PM | File run_exp.py           | Line 27    | Exp instance id = 7740
INFO  | 04/14/2020 05:28:06 PM | File run_exp.py           | Line 28    | Exp comment = None
INFO  | 04/14/2020 05:28:06 PM | File run_exp.py           | Line 29    | Config =
ERROR | 04/14/2020 05:28:06 PM | File run_exp.py           | Line 42    | Traceback (most recent call last):
  File "c:\Users\olive\OneDrive\Dokumenter\GitHub\GRAN\run_exp.py", line 36, in main
    runner = eval(config.runner)(config)
  File "c:\Users\olive\OneDrive\Dokumenter\GitHub\GRAN\runner\gran_runner.py", line 126, in __init__
    self.graphs = create_graphs(config.dataset.name, data_dir=config.dataset.data_path)
  File "c:\Users\olive\OneDrive\Dokumenter\GitHub\GRAN\utils\data_helper.py", line 218, in create_graphs
    num_nodes = [gg.number_of_nodes() for gg in graphs]
  File "c:\Users\olive\OneDrive\Dokumenter\GitHub\GRAN\utils\data_helper.py", line 218, in <listcomp>
    num_nodes = [gg.number_of_nodes() for gg in graphs]
AttributeError: 'NoneType' object has no attribute 'number_of_nodes'

